[2025-04-12T03:07:13.587+0000] {local_task_job_runner.py:123} INFO - ::group::Pre task execution logs
[2025-04-12T03:07:13.620+0000] {taskinstance.py:2614} INFO - Dependencies all met for dep_context=non-requeueable deps ti=<TaskInstance: test_dag.hello_world scheduled__2025-04-11T00:00:00+00:00 [queued]>
[2025-04-12T03:07:13.636+0000] {taskinstance.py:2614} INFO - Dependencies all met for dep_context=requeueable deps ti=<TaskInstance: test_dag.hello_world scheduled__2025-04-11T00:00:00+00:00 [queued]>
[2025-04-12T03:07:13.637+0000] {taskinstance.py:2867} INFO - Starting attempt 1 of 1
[2025-04-12T03:07:13.825+0000] {taskinstance.py:2890} INFO - Executing <Task(BashOperator): hello_world> on 2025-04-11 00:00:00+00:00
[2025-04-12T03:07:13.841+0000] {warnings.py:112} WARNING - /home/***/.local/lib/python3.12/site-packages/***/task/task_runner/standard_task_runner.py:70: DeprecationWarning: This process (pid=680) is multi-threaded, use of fork() may lead to deadlocks in the child.
  pid = os.fork()

[2025-04-12T03:07:13.845+0000] {standard_task_runner.py:72} INFO - Started process 691 to run task
[2025-04-12T03:07:13.844+0000] {standard_task_runner.py:104} INFO - Running: ['***', 'tasks', 'run', 'test_dag', 'hello_world', 'scheduled__2025-04-11T00:00:00+00:00', '--job-id', '24', '--raw', '--subdir', 'DAGS_FOLDER/testdag.py', '--cfg-path', '/tmp/tmpm90d7tbw']
[2025-04-12T03:07:13.847+0000] {standard_task_runner.py:105} INFO - Job 24: Subtask hello_world
[2025-04-12T03:07:13.926+0000] {task_command.py:467} INFO - Running <TaskInstance: test_dag.hello_world scheduled__2025-04-11T00:00:00+00:00 [running]> on host e65636ce49e4
[2025-04-12T03:07:14.052+0000] {taskinstance.py:3134} INFO - Exporting env vars: AIRFLOW_CTX_DAG_OWNER='***' AIRFLOW_CTX_DAG_ID='test_dag' AIRFLOW_CTX_TASK_ID='hello_world' AIRFLOW_CTX_EXECUTION_DATE='2025-04-11T00:00:00+00:00' AIRFLOW_CTX_TRY_NUMBER='1' AIRFLOW_CTX_DAG_RUN_ID='scheduled__2025-04-11T00:00:00+00:00'
[2025-04-12T03:07:14.055+0000] {logging_mixin.py:190} INFO - Task instance is in running state
[2025-04-12T03:07:14.056+0000] {logging_mixin.py:190} INFO -  Previous state of the Task instance: queued
[2025-04-12T03:07:14.057+0000] {logging_mixin.py:190} INFO - Current task name:hello_world state:running start_date:2025-04-12 03:07:13.621062+00:00
[2025-04-12T03:07:14.058+0000] {logging_mixin.py:190} INFO - Dag name:test_dag and current dag run status:running
[2025-04-12T03:07:14.058+0000] {taskinstance.py:732} INFO - ::endgroup::
[2025-04-12T03:07:14.060+0000] {subprocess.py:78} INFO - Tmp dir root location: /tmp
[2025-04-12T03:07:14.066+0000] {subprocess.py:88} INFO - Running command: ['/usr/bin/bash', '-c', 'Hello World!']
[2025-04-12T03:07:14.121+0000] {subprocess.py:99} INFO - Output:
[2025-04-12T03:07:14.130+0000] {subprocess.py:106} INFO - /usr/bin/bash: line 1: Hello: command not found
[2025-04-12T03:07:14.132+0000] {subprocess.py:110} INFO - Command exited with return code 127
[2025-04-12T03:07:14.162+0000] {taskinstance.py:3313} ERROR - Task failed with exception
Traceback (most recent call last):
  File "/home/airflow/.local/lib/python3.12/site-packages/airflow/models/taskinstance.py", line 768, in _execute_task
    result = _execute_callable(context=context, **execute_callable_kwargs)
             ^^^^^^^^^^^^^^^^^^^^^^^^^^^^^^^^^^^^^^^^^^^^^^^^^^^^^^^^^^^^^
  File "/home/airflow/.local/lib/python3.12/site-packages/airflow/models/taskinstance.py", line 734, in _execute_callable
    return ExecutionCallableRunner(
           ^^^^^^^^^^^^^^^^^^^^^^^^
  File "/home/airflow/.local/lib/python3.12/site-packages/airflow/utils/operator_helpers.py", line 252, in run
    return self.func(*args, **kwargs)
           ^^^^^^^^^^^^^^^^^^^^^^^^^^
  File "/home/airflow/.local/lib/python3.12/site-packages/airflow/models/baseoperator.py", line 424, in wrapper
    return func(self, *args, **kwargs)
           ^^^^^^^^^^^^^^^^^^^^^^^^^^^
  File "/home/airflow/.local/lib/python3.12/site-packages/airflow/operators/bash.py", line 276, in execute
    raise AirflowException(
airflow.exceptions.AirflowException: Bash command failed. The command returned a non-zero exit code 127.
[2025-04-12T03:07:14.178+0000] {logging_mixin.py:190} INFO - Task instance in failure state
[2025-04-12T03:07:14.180+0000] {logging_mixin.py:190} INFO - Task start:2025-04-12 03:07:13.621062+00:00 end:2025-04-12 03:07:14.175555+00:00 duration:0.554493
[2025-04-12T03:07:14.182+0000] {logging_mixin.py:190} INFO - Task:<Task(BashOperator): hello_world> dag:<DAG: test_dag> dagrun:<DagRun test_dag @ 2025-04-11 00:00:00+00:00: scheduled__2025-04-11T00:00:00+00:00, state:running, queued_at: 2025-04-12 03:06:44.508415+00:00. externally triggered: False>
[2025-04-12T03:07:14.185+0000] {logging_mixin.py:190} INFO - Failure caused by Bash command failed. The command returned a non-zero exit code 127.
[2025-04-12T03:07:14.186+0000] {taskinstance.py:1226} INFO - Marking task as FAILED. dag_id=test_dag, task_id=hello_world, run_id=scheduled__2025-04-11T00:00:00+00:00, execution_date=20250411T000000, start_date=20250412T030713, end_date=20250412T030714
[2025-04-12T03:07:14.258+0000] {taskinstance.py:341} INFO - ::group::Post task execution logs
[2025-04-12T03:07:14.260+0000] {standard_task_runner.py:124} ERROR - Failed to execute job 24 for task hello_world (Bash command failed. The command returned a non-zero exit code 127.; 691)
Traceback (most recent call last):
  File "/home/airflow/.local/lib/python3.12/site-packages/airflow/task/task_runner/standard_task_runner.py", line 117, in _start_by_fork
    ret = args.func(args, dag=self.dag)
          ^^^^^^^^^^^^^^^^^^^^^^^^^^^^^
  File "/home/airflow/.local/lib/python3.12/site-packages/airflow/cli/cli_config.py", line 49, in command
    return func(*args, **kwargs)
           ^^^^^^^^^^^^^^^^^^^^^
  File "/home/airflow/.local/lib/python3.12/site-packages/airflow/utils/cli.py", line 116, in wrapper
    return f(*args, **kwargs)
           ^^^^^^^^^^^^^^^^^^
  File "/home/airflow/.local/lib/python3.12/site-packages/airflow/cli/commands/task_command.py", line 483, in task_run
    task_return_code = _run_task_by_selected_method(args, _dag, ti)
                       ^^^^^^^^^^^^^^^^^^^^^^^^^^^^^^^^^^^^^^^^^^^^
  File "/home/airflow/.local/lib/python3.12/site-packages/airflow/cli/commands/task_command.py", line 256, in _run_task_by_selected_method
    return _run_raw_task(args, ti)
           ^^^^^^^^^^^^^^^^^^^^^^^
  File "/home/airflow/.local/lib/python3.12/site-packages/airflow/cli/commands/task_command.py", line 341, in _run_raw_task
    return ti._run_raw_task(
           ^^^^^^^^^^^^^^^^^
  File "/home/airflow/.local/lib/python3.12/site-packages/airflow/utils/session.py", line 97, in wrapper
    return func(*args, session=session, **kwargs)
           ^^^^^^^^^^^^^^^^^^^^^^^^^^^^^^^^^^^^^^
  File "/home/airflow/.local/lib/python3.12/site-packages/airflow/models/taskinstance.py", line 3006, in _run_raw_task
    return _run_raw_task(
           ^^^^^^^^^^^^^^
  File "/home/airflow/.local/lib/python3.12/site-packages/airflow/models/taskinstance.py", line 274, in _run_raw_task
    TaskInstance._execute_task_with_callbacks(
  File "/home/airflow/.local/lib/python3.12/site-packages/airflow/models/taskinstance.py", line 3161, in _execute_task_with_callbacks
    result = self._execute_task(context, task_orig)
             ^^^^^^^^^^^^^^^^^^^^^^^^^^^^^^^^^^^^^^
  File "/home/airflow/.local/lib/python3.12/site-packages/airflow/models/taskinstance.py", line 3185, in _execute_task
    return _execute_task(self, context, task_orig)
           ^^^^^^^^^^^^^^^^^^^^^^^^^^^^^^^^^^^^^^^
  File "/home/airflow/.local/lib/python3.12/site-packages/airflow/models/taskinstance.py", line 768, in _execute_task
    result = _execute_callable(context=context, **execute_callable_kwargs)
             ^^^^^^^^^^^^^^^^^^^^^^^^^^^^^^^^^^^^^^^^^^^^^^^^^^^^^^^^^^^^^
  File "/home/airflow/.local/lib/python3.12/site-packages/airflow/models/taskinstance.py", line 734, in _execute_callable
    return ExecutionCallableRunner(
           ^^^^^^^^^^^^^^^^^^^^^^^^
  File "/home/airflow/.local/lib/python3.12/site-packages/airflow/utils/operator_helpers.py", line 252, in run
    return self.func(*args, **kwargs)
           ^^^^^^^^^^^^^^^^^^^^^^^^^^
  File "/home/airflow/.local/lib/python3.12/site-packages/airflow/models/baseoperator.py", line 424, in wrapper
    return func(self, *args, **kwargs)
           ^^^^^^^^^^^^^^^^^^^^^^^^^^^
  File "/home/airflow/.local/lib/python3.12/site-packages/airflow/operators/bash.py", line 276, in execute
    raise AirflowException(
airflow.exceptions.AirflowException: Bash command failed. The command returned a non-zero exit code 127.
[2025-04-12T03:07:14.308+0000] {local_task_job_runner.py:266} INFO - Task exited with return code 1
[2025-04-12T03:07:14.347+0000] {taskinstance.py:3901} INFO - 0 downstream tasks scheduled from follow-on schedule check
[2025-04-12T03:07:14.357+0000] {local_task_job_runner.py:245} INFO - ::endgroup::
