[2025-04-11T01:50:08.637+0000] {local_task_job_runner.py:123} INFO - ::group::Pre task execution logs
[2025-04-11T01:50:08.701+0000] {taskinstance.py:2614} INFO - Dependencies all met for dep_context=non-requeueable deps ti=<TaskInstance: test_dag.hello_world scheduled__2025-04-10T00:00:00+00:00 [queued]>
[2025-04-11T01:50:08.734+0000] {taskinstance.py:2614} INFO - Dependencies all met for dep_context=requeueable deps ti=<TaskInstance: test_dag.hello_world scheduled__2025-04-10T00:00:00+00:00 [queued]>
[2025-04-11T01:50:08.735+0000] {taskinstance.py:2867} INFO - Starting attempt 1 of 1
[2025-04-11T01:50:08.823+0000] {taskinstance.py:2890} INFO - Executing <Task(BashOperator): hello_world> on 2025-04-10 00:00:00+00:00
[2025-04-11T01:50:08.887+0000] {warnings.py:112} WARNING - /home/***/.local/lib/python3.12/site-packages/***/task/task_runner/standard_task_runner.py:70: DeprecationWarning: This process (pid=319) is multi-threaded, use of fork() may lead to deadlocks in the child.
  pid = os.fork()

[2025-04-11T01:50:08.892+0000] {standard_task_runner.py:72} INFO - Started process 330 to run task
[2025-04-11T01:50:08.895+0000] {standard_task_runner.py:104} INFO - Running: ['***', 'tasks', 'run', 'test_dag', 'hello_world', 'scheduled__2025-04-10T00:00:00+00:00', '--job-id', '18', '--raw', '--subdir', 'DAGS_FOLDER/testdag.py', '--cfg-path', '/tmp/tmp1rkxmh62']
[2025-04-11T01:50:08.900+0000] {standard_task_runner.py:105} INFO - Job 18: Subtask hello_world
[2025-04-11T01:50:09.355+0000] {task_command.py:467} INFO - Running <TaskInstance: test_dag.hello_world scheduled__2025-04-10T00:00:00+00:00 [running]> on host e65636ce49e4
[2025-04-11T01:50:09.490+0000] {taskinstance.py:3134} INFO - Exporting env vars: AIRFLOW_CTX_DAG_OWNER='***' AIRFLOW_CTX_DAG_ID='test_dag' AIRFLOW_CTX_TASK_ID='hello_world' AIRFLOW_CTX_EXECUTION_DATE='2025-04-10T00:00:00+00:00' AIRFLOW_CTX_TRY_NUMBER='1' AIRFLOW_CTX_DAG_RUN_ID='scheduled__2025-04-10T00:00:00+00:00'
[2025-04-11T01:50:09.492+0000] {logging_mixin.py:190} INFO - Task instance is in running state
[2025-04-11T01:50:09.493+0000] {logging_mixin.py:190} INFO -  Previous state of the Task instance: queued
[2025-04-11T01:50:09.494+0000] {logging_mixin.py:190} INFO - Current task name:hello_world state:running start_date:2025-04-11 01:50:08.708302+00:00
[2025-04-11T01:50:09.495+0000] {logging_mixin.py:190} INFO - Dag name:test_dag and current dag run status:running
[2025-04-11T01:50:09.496+0000] {taskinstance.py:732} INFO - ::endgroup::
[2025-04-11T01:50:09.497+0000] {subprocess.py:78} INFO - Tmp dir root location: /tmp
[2025-04-11T01:50:09.499+0000] {subprocess.py:88} INFO - Running command: ['/usr/bin/bash', '-c', 'Hello World!']
[2025-04-11T01:50:09.517+0000] {subprocess.py:99} INFO - Output:
[2025-04-11T01:50:09.520+0000] {subprocess.py:106} INFO - /usr/bin/bash: line 1: Hello: command not found
[2025-04-11T01:50:09.522+0000] {subprocess.py:110} INFO - Command exited with return code 127
[2025-04-11T01:50:09.539+0000] {taskinstance.py:3313} ERROR - Task failed with exception
Traceback (most recent call last):
  File "/home/airflow/.local/lib/python3.12/site-packages/airflow/models/taskinstance.py", line 768, in _execute_task
    result = _execute_callable(context=context, **execute_callable_kwargs)
             ^^^^^^^^^^^^^^^^^^^^^^^^^^^^^^^^^^^^^^^^^^^^^^^^^^^^^^^^^^^^^
  File "/home/airflow/.local/lib/python3.12/site-packages/airflow/models/taskinstance.py", line 734, in _execute_callable
    return ExecutionCallableRunner(
           ^^^^^^^^^^^^^^^^^^^^^^^^
  File "/home/airflow/.local/lib/python3.12/site-packages/airflow/utils/operator_helpers.py", line 252, in run
    return self.func(*args, **kwargs)
           ^^^^^^^^^^^^^^^^^^^^^^^^^^
  File "/home/airflow/.local/lib/python3.12/site-packages/airflow/models/baseoperator.py", line 424, in wrapper
    return func(self, *args, **kwargs)
           ^^^^^^^^^^^^^^^^^^^^^^^^^^^
  File "/home/airflow/.local/lib/python3.12/site-packages/airflow/operators/bash.py", line 276, in execute
    raise AirflowException(
airflow.exceptions.AirflowException: Bash command failed. The command returned a non-zero exit code 127.
[2025-04-11T01:50:09.547+0000] {logging_mixin.py:190} INFO - Task instance in failure state
[2025-04-11T01:50:09.548+0000] {logging_mixin.py:190} INFO - Task start:2025-04-11 01:50:08.708302+00:00 end:2025-04-11 01:50:09.545696+00:00 duration:0.837394
[2025-04-11T01:50:09.549+0000] {logging_mixin.py:190} INFO - Task:<Task(BashOperator): hello_world> dag:<DAG: test_dag> dagrun:<DagRun test_dag @ 2025-04-10 00:00:00+00:00: scheduled__2025-04-10T00:00:00+00:00, state:running, queued_at: 2025-04-11 01:49:30.530450+00:00. externally triggered: False>
[2025-04-11T01:50:09.550+0000] {logging_mixin.py:190} INFO - Failure caused by Bash command failed. The command returned a non-zero exit code 127.
[2025-04-11T01:50:09.551+0000] {taskinstance.py:1226} INFO - Marking task as FAILED. dag_id=test_dag, task_id=hello_world, run_id=scheduled__2025-04-10T00:00:00+00:00, execution_date=20250410T000000, start_date=20250411T015008, end_date=20250411T015009
[2025-04-11T01:50:09.595+0000] {taskinstance.py:341} INFO - ::group::Post task execution logs
[2025-04-11T01:50:09.596+0000] {standard_task_runner.py:124} ERROR - Failed to execute job 18 for task hello_world (Bash command failed. The command returned a non-zero exit code 127.; 330)
Traceback (most recent call last):
  File "/home/airflow/.local/lib/python3.12/site-packages/airflow/task/task_runner/standard_task_runner.py", line 117, in _start_by_fork
    ret = args.func(args, dag=self.dag)
          ^^^^^^^^^^^^^^^^^^^^^^^^^^^^^
  File "/home/airflow/.local/lib/python3.12/site-packages/airflow/cli/cli_config.py", line 49, in command
    return func(*args, **kwargs)
           ^^^^^^^^^^^^^^^^^^^^^
  File "/home/airflow/.local/lib/python3.12/site-packages/airflow/utils/cli.py", line 116, in wrapper
    return f(*args, **kwargs)
           ^^^^^^^^^^^^^^^^^^
  File "/home/airflow/.local/lib/python3.12/site-packages/airflow/cli/commands/task_command.py", line 483, in task_run
    task_return_code = _run_task_by_selected_method(args, _dag, ti)
                       ^^^^^^^^^^^^^^^^^^^^^^^^^^^^^^^^^^^^^^^^^^^^
  File "/home/airflow/.local/lib/python3.12/site-packages/airflow/cli/commands/task_command.py", line 256, in _run_task_by_selected_method
    return _run_raw_task(args, ti)
           ^^^^^^^^^^^^^^^^^^^^^^^
  File "/home/airflow/.local/lib/python3.12/site-packages/airflow/cli/commands/task_command.py", line 341, in _run_raw_task
    return ti._run_raw_task(
           ^^^^^^^^^^^^^^^^^
  File "/home/airflow/.local/lib/python3.12/site-packages/airflow/utils/session.py", line 97, in wrapper
    return func(*args, session=session, **kwargs)
           ^^^^^^^^^^^^^^^^^^^^^^^^^^^^^^^^^^^^^^
  File "/home/airflow/.local/lib/python3.12/site-packages/airflow/models/taskinstance.py", line 3006, in _run_raw_task
    return _run_raw_task(
           ^^^^^^^^^^^^^^
  File "/home/airflow/.local/lib/python3.12/site-packages/airflow/models/taskinstance.py", line 274, in _run_raw_task
    TaskInstance._execute_task_with_callbacks(
  File "/home/airflow/.local/lib/python3.12/site-packages/airflow/models/taskinstance.py", line 3161, in _execute_task_with_callbacks
    result = self._execute_task(context, task_orig)
             ^^^^^^^^^^^^^^^^^^^^^^^^^^^^^^^^^^^^^^
  File "/home/airflow/.local/lib/python3.12/site-packages/airflow/models/taskinstance.py", line 3185, in _execute_task
    return _execute_task(self, context, task_orig)
           ^^^^^^^^^^^^^^^^^^^^^^^^^^^^^^^^^^^^^^^
  File "/home/airflow/.local/lib/python3.12/site-packages/airflow/models/taskinstance.py", line 768, in _execute_task
    result = _execute_callable(context=context, **execute_callable_kwargs)
             ^^^^^^^^^^^^^^^^^^^^^^^^^^^^^^^^^^^^^^^^^^^^^^^^^^^^^^^^^^^^^
  File "/home/airflow/.local/lib/python3.12/site-packages/airflow/models/taskinstance.py", line 734, in _execute_callable
    return ExecutionCallableRunner(
           ^^^^^^^^^^^^^^^^^^^^^^^^
  File "/home/airflow/.local/lib/python3.12/site-packages/airflow/utils/operator_helpers.py", line 252, in run
    return self.func(*args, **kwargs)
           ^^^^^^^^^^^^^^^^^^^^^^^^^^
  File "/home/airflow/.local/lib/python3.12/site-packages/airflow/models/baseoperator.py", line 424, in wrapper
    return func(self, *args, **kwargs)
           ^^^^^^^^^^^^^^^^^^^^^^^^^^^
  File "/home/airflow/.local/lib/python3.12/site-packages/airflow/operators/bash.py", line 276, in execute
    raise AirflowException(
airflow.exceptions.AirflowException: Bash command failed. The command returned a non-zero exit code 127.
[2025-04-11T01:50:09.635+0000] {local_task_job_runner.py:266} INFO - Task exited with return code 1
[2025-04-11T01:50:09.813+0000] {taskinstance.py:3901} INFO - 0 downstream tasks scheduled from follow-on schedule check
[2025-04-11T01:50:09.817+0000] {local_task_job_runner.py:245} INFO - ::endgroup::
